An NVIDIA GPU may be present on this machine, but a CUDA-enabled jaxlib is not installed. Falling back to cpu.
JIT session error: Cannot allocate memory
jax.errors.SimplifiedTraceback: For simplicity, JAX has removed its internal frames from the traceback of the following exception. Set JAX_TRACEBACK_FILTERING=off to include these.

The above exception was the direct cause of the following exception:

Traceback (most recent call last):
  File "/mnt/nfs/nrdata02-users-data/luciano/script/permABC/figures/sir/sir.py", line 135, in <module>
    smc_reg= perm_abc_smc(key = key, model = mod_reg, y_obs = y_obs_reg, n_particles= N, kernel = KernelTruncatedRW, verbose = 1, epsilon_target = 0., update_weights_distance= False, Final_iteration= Final_iteration, num_blocks_gibbs= n_blocks_reg, both_loc_glob= True, N_iteration_max = N_iterations, alpha_epsilon= alpha)
  File "/mnt/nfs/nrdata02-users-data/luciano/script/permABC/smc.py", line 179, in perm_abc_smc
    thetas[alive], zs[alive], distance_values[alive], ys_index[alive], zs_index[alive], n_lsa, acc_rate, n_sim = move_smc_gibbs_blocks(key = key_move, model = model, thetas = thetas[alive], zs = zs[alive], weights = weights[alive], ys_index = ys_index[alive], zs_index = zs_index[alive], epsilon = epsilon, y_obs = y_obs, distance_values = distance_values[alive], kernel = kernel, H = num_blocks_gibbs, verbose = verbose, both_loc_glob= both_loc_glob, perm = True)
  File "/mnt/nfs/nrdata02-users-data/luciano/script/permABC/moves.py", line 192, in move_smc_gibbs_blocks
    kernel_logratio = backward_kernel_glob.logpdf(thetas[glob_update]) - forward_kernel_glob.logpdf(proposed_thetas_glob[glob_update])
  File "/mnt/nfs/nrdata02-users-data/luciano/script/permABC/kernels.py", line 167, in logpdf
    logpdf_loc = truncnorm.logpdf(thetas_prop.loc, a=a_loc, b=b_loc, loc=self.thetas.loc, scale=self.tau.loc)
  File "/home/users/luciano/miniconda3/envs/permabc_env/lib/python3.10/site-packages/jax/_src/scipy/stats/truncnorm.py", line 75, in logpdf
    val = lax.sub(norm.logpdf(x, loc, scale), _log_gauss_mass(a, b))
  File "/home/users/luciano/miniconda3/envs/permabc_env/lib/python3.10/site-packages/jax/_src/scipy/stats/truncnorm.py", line 42, in _log_gauss_mass
    case_right = a > 0
  File "/home/users/luciano/miniconda3/envs/permabc_env/lib/python3.10/site-packages/jax/_src/numpy/array_methods.py", line 271, in deferring_binary_op
    return binary_op(*args)
jaxlib.xla_extension.XlaRuntimeError: INVALID_ARGUMENT: Symbol main.6 not found.
Traceback (most recent call last):
  File "/mnt/nfs/nrdata02-users-data/luciano/script/permABC/figures/sir/sir_figures.py", line 26, in <module>
    with lzma.open('figures/sir/SIR_results{}.xz'.format(seed), 'rb') as f:
  File "/home/users/luciano/miniconda3/envs/permabc_env/lib/python3.10/lzma.py", line 309, in open
    binary_file = LZMAFile(filename, lz_mode, format=format, check=check,
  File "/home/users/luciano/miniconda3/envs/permabc_env/lib/python3.10/lzma.py", line 120, in __init__
    self._fp = builtins.open(filename, mode)
FileNotFoundError: [Errno 2] No such file or directory: 'figures/sir/SIR_results3.xz'
